<?xml version="1.0"?>
<robot xmlns:xacro="http://www.ros.org/wiki/xacro" name="ae86_bot">

  <!-- argument -->
  <xacro:arg name="use_lidar" default="true"/>

  <!-- properties -->
  <xacro:property name="base_length" value="0.6"/>
  <xacro:property name="base_width"  value="0.4"/>
  <xacro:property name="base_height" value="0.15"/>
  <xacro:property name="wheel_radius" value="0.08"/>
  <xacro:property name="wheel_width"  value="0.04"/>
  <xacro:property name="wheel_x" value="0.16"/>   
  <xacro:property name="wheel_y" value="0.08"/>   
  <xacro:property name="wheel_z" value="0.04"/>   
  <xacro:property name="lidar_z" value="0.12"/>

  <!-- base link -->
  <link name="base_link">
    <visual>
      <origin xyz="0 0 $(eval ${base_height}/2)" rpy="0 0 0"/>
      <geometry>
        <box size="${base_length} ${base_width} ${base_height}"/>
      </geometry>
      <material name="gray">
        <color rgba="0.7 0.7 0.7 1"/>
      </material>
    </visual>
    <collision>
      <origin xyz="0 0 $(eval ${base_height}/2)" rpy="0 0 0"/>
      <geometry>
        <box size="${base_length} ${base_width} ${base_height}"/>
      </geometry>
    </collision>
    <inertial>
      <mass value="8.0"/>
      <origin xyz="0 0 0"/>
      <inertia ixx="0.1" ixy="0.0" ixz="0.0"
               iyy="0.1" iyz="0.0" izz="0.1"/>
    </inertial>
  </link>

  <!-- macro for wheels -->
  <xacro:macro name="wheel" params="name x y">
    <link name="${name}_link">
      <visual>
        <origin xyz="${x} ${y} ${wheel_z}" rpy="0 1.5708 0"/>
        <geometry>
          <cylinder radius="${wheel_radius}" length="${wheel_width}"/>
        </geometry>
        <material name="black">
          <color rgba="0 0 0 1"/>
        </material>
      </visual>
      <collision>
        <origin xyz="${x} ${y} ${wheel_z}" rpy="0 1.5708 0"/>
        <geometry>
          <cylinder radius="${wheel_radius}" length="${wheel_width}"/>
        </geometry>
      </collision>
      <inertial>
        <mass value="1.0"/>
        <origin xyz="0 0 0"/>
        <inertia ixx="0.01" ixy="0.0" ixz="0.0"
                 iyy="0.01" iyz="0.0" izz="0.01"/>
      </inertial>
    </link>
    <joint name="${name}_joint" type="continuous">
      <parent link="base_link"/>
      <child link="${name}_link"/>
      <origin xyz="${x} ${y} ${wheel_z}" rpy="0 0 0"/>
      <axis xyz="0 1 0"/>
    </joint>
  </xacro:macro>

  <!-- four wheels -->
  <xacro:wheel name="wheel_front_left"  x="${wheel_x}"  y="${wheel_y}"/>
  <xacro:wheel name="wheel_front_right" x="${wheel_x}"  y="$(eval -1*${wheel_y})"/>
  <xacro:wheel name="wheel_rear_left"   x="$(eval -1*${wheel_x})" y="${wheel_y}"/>
  <xacro:wheel name="wheel_rear_right"  x="$(eval -1*${wheel_x})" y="$(eval -1*${wheel_y})"/>

  <!-- lidar -->
  <xacro:if value="$(arg use_lidar)">
    <link name="lidar_link">
      <visual>
        <origin xyz="0 0 $(eval ${base_height}/2 + ${lidar_z})" rpy="0 0 0"/>
        <geometry>
          <cylinder radius="0.03" length="0.05"/>
        </geometry>
        <material name="blue">
          <color rgba="0 0 1 1"/>
        </material>
      </visual>
      <collision>
        <origin xyz="0 0 $(eval ${base_height}/2 + ${lidar_z})" rpy="0 0 0"/>
        <geometry>
          <cylinder radius="0.03" length="0.05"/>
        </geometry>
      </collision>
      <inertial>
        <mass value="0.5"/>
        <origin xyz="0 0 0"/>
        <inertia ixx="0.001" ixy="0.0" ixz="0.0"
                 iyy="0.001" iyz="0.0" izz="0.001"/>
      </inertial>
    </link>
    <joint name="lidar_joint" type="fixed">
      <parent link="base_link"/>
      <child link="lidar_link"/>
      <origin xyz="0 0 $(eval ${base_height}/2 + ${lidar_z})" rpy="0 0 0"/>
    </joint>
  </xacro:if>

</robot>
